Workbook

Sheet OKR, KPI 설정
B3: *OKR / KPI / NSM 작성 실습
B4: 1. 현상황 : 카페 24 MS software CEO 운영관리
B5: 2. 비즈니스 목표 : 신규 고객 확보 및 재구매율 증가
B6: No | C6: 구분 | D6: 항목 | E6: 내용
B7: 1 | C7: Obective | D7: 1사분기 재구매율 및 점유율 상승
B8: 2 | C8: Keyresult -1 | D8: 브랜드 평판 지수 10% 상승 달성
C9: Keyresult -2 | D9: B to B 영업률 20% 상승
C10: Keyresult-3 | D10: B to G 영업률 20% 상승 달성
B11: 3 | C11: KPI -1 | D11: MS Software 기업 내부 사용 생태계 확장
C12: KPI - 2 | D12: 내부 사용자 데이터 수집 및 솔루션 제공
B13: 4 | C13: NSM | D13: MAU(*월간 활성 사용자수)확인 | E13: 자사 재품 대비 경쟁사 OA 사용 현황 분석

Sheet Content Marketing process-
B1: *컨텐츠 마케팅 프로세스
B2: step1 : 컨텐츠 마케팅 목표 및 일정 설정
B3: 1. 왜 > 목적 / 신상품 링귀걸이 런칭기념 광고 캠페인
B4: 2. 언제 > 제작일정, 배포시기 : 2개월 전 준비 // 3개월 후 런칭 기념 100일 이벤트
B5: step2 : 타겟 설정 및 메세지 도출
B6: 3. 타겟 설정 및 메세지 도출 : 40대 여성 // 대도시 거주 직장인 여성
B7: 4. 무엇으로 > 마케팅 메세지 : 일상 고급 데일리 귀걸이 / 14K 링귀걸이
B8: step3 : 매체를 지정하고 컨텐츠 가공
B9: 5. 어디에서 > 광고 매체 : 네이버, 구글 ads, 인스타그램
B10: 6. 어떻게 > 컨텐츠 가공 : 타겟 여성과 유사한 사일반 사용자 혹은 인플루언서의 귀걸이 사용

Sheet Sheet4
B2: *컨텐츠 마케팅 프로세스
B3: step1 : 컨텐츠 마케팅 목표 및 일정 설정
B4: 1. 왜 > 목적 / 1사분기 MS office 재구매율 및 점유율 상승
B5: 2. 언제 > 제작일정, 배포시기 : 2개월 전 준비
B6: step2 : 타겟 설정 및 메세지 도출
B7: 3. 타겟 설정 및 메세지 도출 : 기업 및 정부 //
B8: 4. 무엇으로 > 마케팅 메세지 : "신임 조직에는 강력한 협업 도구가 필요합니다 – MS Office로 처음부터 함께하세요."
C9: "처음 만나는 보고서, 처음부터 완성도를 다르게 – Office 365로 스마트하게 시작하세요."
B10: step3 : 매체를 지정하고 컨텐츠 가공
B11: 5. 어디에서 > 광고 매체 : 집적 영업 및 유튜브 광고
B12: 6. 어떻게 > 컨텐츠 가공 : 정부 및 기관, 기업 관계자 맞춤 - 브랜딩 콘텐츠 제작
B14: 1. 현상황 : 카페 24 MS software CEO 운영관리
B15: 2. 비즈니스 목표 : 신규 고객 확보 및 재구매율 증가
B16: No | C16: 구분 | D16: 항목 | E16: 내용
B17: 1 | C17: Obective | D17: 1사분기 재구매율 및 점유율 상승
B18: 2 | C18: Keyresult -1 | D18: 브랜드 평판 지수 10% 상승 달성
C19: Keyresult -2 | D19: B to B 영업률 20% 상승
C20: Keyresult-3 | D20: B to G 영업률 20% 상승 달성
B21: 3 | C21: KPI -1 | D21: MS Software 기업 내부 사용 생태계 확장
C22: KPI - 2 | D22: 내부 사용자 데이터 수집 및 솔루션 제공
B23: 4 | C23: NSM | D23: MAU(*월간 활성 사용자수)확인 | E23: 자사 재품 대비 경쟁사 OA 사용 현황 분석

Sheet WBS 제작 실습
B2: *WBS 제작 실습
B3: 프로젝트명 : 2025 여름 시즌 링귀걸이 프로모션 런칭 이벤트
B4: (1) 전략 기획 단계 | F4: (1) 전략 기획 단계
B5: 항목 | C5: 내용 | F5: 항목 | G5: 내용
B6: OKR / KPI / NSM | C6: O : 7월 내 링귀걸이 제품 인지도 및 판매 확대 | F6: OKR / KPI / NSM | G6: Obective | H6: 1사분기 재구매율 및 점유율 상승
C7: KR - 1 : 총 유입자 수 20,000명 이상 | G7: Keyresult -1 | H7: 브랜드 평판 지수 10% 상승 달성
C8: KR - 2 : 판매 전환 300건 | G8: Keyresult -2 | H8: B to B 영업률 5 상승
C9: KPI - 3 : 리타게팅 전환율 8% 이상 | G9: KPI | H9: “MAU(월간 활성 사용자수) 10% 이상 지속 성장”
C10: NSM : 구매당 평균 광고비용 3,000 이하 | G10: NSM | H10: MAU(*월간 활성 사용자수)확인
B11: 3C 분석 | C11: Company => 자사분석, 우리 브랜드 및 상품의 강점, 약점 등 -> ex.) 가성비있는 가격대 + 트렌드한 디자인 | F11: 3C 분석 | G11: Company => 강점 : 타사 대비 높은 브랜드 인지도, 시장 내 1점유율 / 정부 및 정부 인접 기관, 기업의 국내 Office program 사용
C12: Customer => 2030 여성 / 여름 패션 관심이 많은 여성 | G12: Customer => 40/50 기업 내 조직 관리자 및 준관리자
C13: Competitor => 29cm, 무신사 등 | G13: Competitor => 한컴 및 기타 오피스 프로그램
B14: STP 전략 | C14: Segmentation : 20~34 여성, SNS 및 온라인 쇼핑에 매우 익숙한 여성 | F14: STP 전략 | G14: Segmentation : 40-50대 회사원, 조직 관리급 인사
C15: Targeting : 인스타그램 이용률 높은 Z세대 직장인 | G15: Targeting : 경쟁 오피스 프로그램 사용 조직 or 신사업 확장 및 창업을 시작하려는 조직
C16: Positioning : "매일 부담 없이 바꾸는 여름 주얼리" | G16: Positioning : "신생 기업 및 신사업 확장 기업에서 오피스 프로그램 선택지"
B17: Persona | C17: 이서연(28세, 컨텐츠마케터, 여름시즌 패션에 관심이 많음, 출.퇴근 코디용 주얼리 일주일에 1회 이상 구매 | F17: Persona | G17: 김지호(54세), 퇴사 후 본인이 일했던 분야의 창업을 준비하는 중
B18: contents Marketing | C18: USP(Unique Selling Point) : "가볍고 매일 착용 가능한 데일리 링귀걸이" | F18: contents Marketing | G18: USP(Unique Selling Point) : "새로운 오피스 프로그램, 새로운 효율"
C19: TPO : 출근 룩 / 바캉스 룩 / 페스티벌 시즌 스타일 제안 | G19: TPO : 사업초기 / 오피스 / 오피스 프로그램 제안
B21: (2) 캠페인 설계 단계 | F21: (2) 캠페인 설계 단계
B22: SEO | C22: 주요 키워드 발굴 : #여름 귀걸이, #링귀걸이, #데일리주얼리, # 직장인주얼리 | F22: SEO | G22: 주요 키워드 발굴 : #혁신, #조직, #신사업, # EXEL
B23: 4P | C23: Product : 여름 데일리용 귀걸이 (3종) | F23: 4P | G23: Product : MS OFFICE PROGRAM
C24: Price : 1 + 1 할인 (14,800원) | G24: Price : 3800000
C25: Place : 자사몰, 오픈마켓, 인스타그램 | G25: Place : 자사몰, 오픈마켓, 유튜브
C26: Promotion : 상품 구매 후 우수리뷰 작성 시, 추가 쿠폰 증정 | G26: Promotion : 신생 기업 및 신사업 팀에게 3개월치 무료 구독
B27: 콘텐츠 갤러리 | C27: 7월 1주차 : 제품 소개 영상 | F27: 콘텐츠 갤러리 | G27: 7월 1주차 : 제품 소개 영상
C28: 7월 2주차 : 스타일링 팁 카드뉴스 | G28: 7월 2주차 : 스타일링 팁 카드뉴스
C29: 7월 3주차 : A/B 광고 뉴스 (A안, B안) | G29: 7월 3주차 : A/B 광고 뉴스 (A안, B안)
C30: 7월 4주차 : 구매 후기 리포스트 프로모션 이벤트 | G30: 7월 4주차 : 제품 지속 사용시 할인 적용
B32: (3) 광고 세팅 | F32: (3) 광고 세팅
B33: Media Mix | C33: 인스타그램 : 릴스 + 스토리 광고 (400만원) | F33: Media Mix | G33: 인스타그램 : 릴스 + 스토리 광고 (400만원)
C34: 유튜브 : 쇼츠 (200만원) | G34: 유튜브 : 건너 뛸 수 있는 인스트링 광고 (200만원)
C35: 구글 : 키워드 검색 광고 (300만원) | G35: 구글 : 키워드 검색 광고 (300만원)
C36: 카페 : 카페 커뮤니티 배너광고(100만원) | G36: 카페 : 카페 커뮤니티 배너광고(100만원)
B37: 채널별 광고 생성 | C37: Meta 비즈니스 관리자 : 릴수, 스토리 캠페인 세팅 | F37: 채널별 광고 생성 | G37: Meta 비즈니스 관리자 : 릴수, 스토리 캠페인 세팅
C38: 구글애즈 : 광고 캠페인 세팅 | G38: 구글애즈 : 광고 캠페인 세팅
C39: 카페 : 광고 문의 활용 배너 제작 및 일정 부킹 | G39: 카페 : 광고 문의 활용 배너 제작 및 일정 부킹
B40: UTM URL | C40: httos://cromidi.cafe24.com?utm_source=instagram | F40: UTM URL | G40: https://sagejin99.cafe25.com/?&utm_source=google&utm_midiume=cpc&beauty_campaign=2025_summer_MS&utm_term=MS_Office&utm_term=0707_MS_adv
B41: GA4 + GTM 이벤트 구성 | C41: "구매하기" 버튼 클릭 이벤트 세팅 | F41: GA4 + GTM 이벤트 구성 | G41: "구매하기" 버튼 클릭 이벤트 세팅
C42: 실제 구매까지 퍼널마케팅 분석 => 이탈률이 많은 구간 파악 | G42: 실제 구매까지 퍼널마케팅 분석 => 이탈률이 많은 구간 파악
C43: 리타게팅을 하기 위한 잠재고객 분류 설정 | G43: 리타게팅을 하기 위한 잠재고객 분류 설정
...

Sheet Funnel 전략
A2: *Funnel 전략 프로세스
A3: -상품,세탁세제
B4: 퍼널단계 | C4: 고객상태 | D4: 콘텐츠 내용 | G4: 콘텐츠 타입
B5: Attention | C5: "처음 들어본 브랜드" | D5: "친환경 세제 관련 인포그래픽 카드뉴스 / 집에서 실천 지구 살리기/ 친환경 용품 피부 및 기타 유익정보" | G5: 인포그래픽 카드 뉴스, 이미지 정보
B6: Interested | C6: "친환경이 뭔지 모르지만 유익한 것 같아" | D6: "친환경 관련 밈/노래/숏폼 등 / 친환경 관련 기타 정보 및 상품에 대한 호기심" =>생각보다 친환경 어렵지 않다!" | G6: 숏폼, 릴스, 로고송
B7: Search | C7: "그래서 친환경 상품이 뭐가 있는데?" | D7: "상품에 대한 기초정보제공 혹은 샘플링을 활용한 사용유도" => 설문조사 응해주면 샘플 발송! | G7: 샘플링
B8: Action | C8: "실제 사용해보니 정말 괜찮네!!" | D8: "친환경 상품을 직접 구매할 수 있도록 유도 -> 지금 구매하면 1 + 1" 20% 할인 한정인원 제공!! | G8: 할인쿠폰 1+1 이벤트
B9: Sharing | C9: "이 정보 나만 알기에는 아까워-!" | D9: "이 url을 공유해서 지인 추천 받는다면 추가 할인 혜택 제공" | G9: QR 코드
B10: Attention | C10: "이 상품이 나름 괜찮은거 같은데?" | D10: "친환경 관련 밈/노래/숏폼 등 / 친환경 관련 기타 정보 및 상품에 대한 호기심" =>생각보다 친환경 어렵지 않다!" | G10: 할인쿠폰 1+1 이벤트
B11: Activation | C11: "어차피 필요한데 그럼 한 번 구매해볼까?" | D11: 실제 상품 구매 확정 및 액션 실행
B12: Retention | C12: "지난번 사용 시 정말 괜찮았어" | D12: "상품 재구매 유도를 위한 장치 / 첫 상품 구매 후 1개월 내 사용 가능한 쿠폰" | G12: 할인쿠폰
B13: Revenue | C13: "나는 이제 이 세제로 정착할래!" | D13: 멤버십 가입 유도 혹은 구독결제 서비스를 활용해서 충성고객으로 전환 시킴 / 타 상품 구매 x | G13: 멤버십 제도
B14: Referral | C14: "주변 사람들한테 적극 알려야지!" | D14: 우리의 상품을 알아서 자발적으로 홍보해줌, 바이럴 효과 생성 / | G14: CRM
A17: *Funnel 전략 프로세스
A18: -MS office
B19: 퍼널단계 | C19: 고객상태 | D19: 콘텐츠 내용 | G19: 콘텐츠 타입
B20: Attention | C20: "처음 들어본 브랜드" | D20: "MS office를 사용한 흥미 유발 퍼포먼스(Ex, excelle 그림 그리기, PPT 작업을 이용한 스토리텔링 동영상 제작" | G20: 인포그래픽 카드 뉴스, 이미지 정보
B21: Interested | C21: "MS이 뭔지 모르지만 유익한 것 같아" | D21: "숏폼, SNS를 이용한 MS office의 활용성과 시각적 데이터 효과, 디자인 레이아웃 효과르 보여줌" => | F21: >"유익한MS!" | G21: 숏폼, 릴스, 로고송
B22: Search | C22: "그래서 MS office 프로그램이 뭐가 있는데?" | D22: "Office의 최신 기술 소개, 타 Office 프로그램과 차별화된 요소, 그리고 폭넓은 선택옵션 보여줌" | G22: 샘플링
B23: Action | C23: "실제 사용해보니 정말 괜찮네!!" | D23: "Office를 구독하며 연계상품 무료 체험 ex) OneDrive 3개월 구독 무료, Office 구매 시 Adobe Primiume 1개월 체험" | G23: 할인쿠폰 1+1 이벤트
B24: Sharing | C24: "이 정보 나만 알기에는 아까워-!" | D24: "Office를 이용해 생산성이 향상된 스토리를 카드뉴스 및 리뷰로 공모, 공유 시 연계 상품 무료 기간 제공" | G24: QR 코드
B25: Attention | C25: "이 상품이 나름 괜찮은거 같은데?" | D25: " | G25: 할인쿠폰 1+1 이벤트
B26: Activation | C26: "어차피 필요한데 그럼 한 번 구매해볼까?"
B27: Retention | C27: "지난번 사용 시 정말 괜찮았어" | G27: 할인쿠폰
B28: Revenue | C28: "나는 이제 이 세제로 정착할래!" | G28: 멤버십 제도
B29: Referral | C29: "주변 사람들한테 적극 알려야지!" | G29: CRM

Sheet UTL 빌더
A2: *Funnel 전략 프로세스
B3: UTML Builder
B4: No | C4: 광고매체 | D4: 매체종류 | E4: 키워드 | F4: 캠페인 | G4: 콘텐츠 | H4: 비고 | J4: 웹사이트 URL | K4: 소스 | L4: 매체 | M4: 캠페인 | N4: 키워드 | O4: 콘텐츠 | P4: 키워드여부 | Q4: 콘텐츠 여부 | R4: url
C5: 소스(Source) | D5: 매체(Medium) | F5: 캠페인(campaign) | G5: 콘텐츠(Content)
B6: 1 | C6: naver | D6: sabrweb | E6: 이니스프리 | F6: 2025_summer_event | G6: 0701_thumb1 | J6: https://sagejin99.cafe24.com/ | K6: naver | L6: sabrweb | M6: 2025_summer_event | N6: 이니스프리 | O6: 0701_thumb2 | P6: =IF(N6="","x","o") -> o | Q6: =IF(O6="","x","o") -> o | R6: =J6&IF(ISERR(FIND("?",J6)),"?","&")&"&utm_source="&K6&"&utm_midiume="&L6&"&beauty_campaign="&M6&IF(P6="o","&utm_term="&N6,"")&IF(Q6="o","&utm_term="&O6,"") -> https://sagejin99.cafe24.com/?&utm_source=naver&utm_midiume=sabrweb&beauty_campaign=2025_summer_event&utm_term=이니스프리&utm_term=0701_thumb2
B7: 2 | C7: instagram | D7: feed | E7: 감성패션 | F7: 2025_moodlay_event1 | G7: 0728_main1
B8: 3 | C8: instagram | D8: feed | E8: 이니스프리 | F8: 2025_summer_event | G8: 0701_thumb2 | J8: https://sagejin99.cafe25.com/ | K8: google | L8: cpc | M8: 2025_summer_MS | N8: MS_Office | O8: 0707_MS_adv | P8: =IF(N8="","x","o") -> o | Q8: =IF(O8="","x","o") -> o | R8: =J8&IF(ISERR(FIND("?",J8)),"?","&")&"&utm_source="&K8&"&utm_midiume="&L8&"&beauty_campaign="&M8&IF(P8="o","&utm_term="&N8,"")&IF(Q8="o","&utm_term="&O8,"") -> https://sagejin99.cafe25.com/?&utm_source=google&utm_midiume=cpc&beauty_campaign=2025_summer_MS&utm_term=MS_Office&utm_term=0707_MS_adv

Sheet 간단
A1: * 스케줄캘린더 제작실습
A2: 업무 | B2: Weak1(7/1-7) | C2: weak2(7/8-14) | D2: weak3(7/15-21) | E2: weak4(7/22-29)
A3: *스케줄캘린더 제작실습
A4: 프로젝트명
A5: 업무
A6: 전략기획
A7: 콘텐츠 기획
A8: 광고/SEO 전략 설계
A9: 콘텐츠 제작
A10: 광고 채널 세팅
A11: 콘텐츠 배포
A12: A/B 테스트
A13: 실시간 성과 모니터링
A14: KPI 분석 및 보고서

Sheet RoAS 실습
A1: * RoAS 계산 실습
A3: - 총 광고비
A4: -총 매출
A5: - 평균 RoAS : | B5: =AVERAGE(I7,I8,I9) -> 2.7777778
A6: 채널 | B6: 광고비 | C6: 노출수 | D6: 클릭수 | E6: 전환수 | F6: 매출 | G6: CTR | H6: CPA | I6: RoAS
A7: Instgram | B7: 4000000 | C7: 400000 | D7: 8000 | E7: 400 | F7: 12000000 | G7: =D7/C7 -> 0.02 | H7: =B7/E7 -> 10000 | I7: =F7/B7 -> 3
A8: Google Search | B8: 3000000 | C8: 50000 | D8: 4000 | E8: 200 | F8: 10000000 | G8: =D8/C8 -> 0.08 | H8: =B8/E8 -> 15000 | I8: =F8/B8 -> 3.3333333
A9: Youtne | B9: 3000000 | C9: 200000 | D9: 2000 | E9: 80 | F9: 6000000 | G9: =D9/C9 -> 0.01 | H9: =B9/E9 -> 37500 | I9: =F9/B9 -> 2
A10: 합계 | B10: 10000000

Sheet RoAS 실습 미션
A1: * RoAS 계산 실습
A2: - 총 광고비 : | B2: =SUM(B6,B7,B8) -> 10000000
A3: -총 매출 : | B3: =SUM(F6,F7,F8) -> 34500000
A4: - 평균 RoAS : | B4: =AVERAGE(I6,I7,I8) -> 3.5
A5: 채널 | B5: 광고비 | C5: 노출수 | D5: 클릭수 | E5: 전환수 | F5: 매출 | G5: CTR | H5: CPA | I5: RoAS
A6: Instgram | B6: 4000000 | C6: 400000 | D6: 8000 | E6: 400 | F6: 12000000 | G6: =D6/C6 -> 0.02 | H6: =B6/E6 -> 10000 | I6: =F6/B6 -> 3
A7: Google Search | B7: 3000000 | C7: 50000 | D7: 4000 | E7: 200 | F7: 10900000 | G7: =D7/C7 -> 0.08 | H7: =B7/E7 -> 15000 | I7: =F7/B7 -> 3.6333333
A8: Youtne | B8: 3000000 | C8: 200000 | D8: 2000 | E8: 200 | F8: 11600000 | G8: =D8/C8 -> 0.01 | H8: =B8/E8 -> 15000 | I8: =F8/B8 -> 3.8666667
A9: 합계 | B9: 10000000

Sheet ROI 실습
A1: * ROI 계산 실습
A2: - 총 광고비 : | B2: =SUM(B8,B9,B10) -> 10000000
A3: -총 매출 : | B3: =SUM(F8,F9,F10) -> 34500000
A4: (이익 - 광고비)/광고비 * 100
A5: 영업이익률 | B5: 0.4
A6: - 소비자가 ; | B6: 30000
A7: 채널 | B7: 광고비 | C7: 노출수 | D7: 클릭수 | E7: 전환수 | F7: 매출 | G7: CTR | H7: CPA | I7: RoAS | J7: ROI
A8: Instgram | B8: 3000000 | C8: 400000 | D8: 8000 | E8: 400 | F8: 12000000 | G8: =D8/C8 -> 0.02 | H8: =B8/E8 -> 7500 | I8: =F8/B8 -> 4 | J8: =(F8*$B$5-B8)/B8 -> 0.6
A9: Google Search | B9: 4000000 | C9: 50000 | D9: 4000 | E9: 200 | F9: 10900000 | G9: =D9/C9 -> 0.08 | H9: =B9/E9 -> 20000 | I9: =F9/B9 -> 2.725 | J9: =(F9*$B$5-B9)/B9 -> 0.09
A10: Youtne | B10: 3000000 | C10: 200000 | D10: 2000 | E10: 200 | F10: 11600000 | G10: =D10/C10 -> 0.01 | H10: =B10/E10 -> 15000 | I10: =F10/B10 -> 3.8666667 | J10: =(F10*$B$5-B10)/B10 -> 0.54666667
A11: 합계 | B11: 10000000

Sheet 3C 분석 시트
A2: *3C 분석시트 작성
A3: 브랜드명 : 왓챠
A4: 카테고리 | B4: 분석 내용 | C4: 광고비 | D4: 광고비 | E4: 광고비 | F4: 내용
A5: Company(자사분석) | B5: 브랜드명, 내부강점, 약점, 자산(기회요소), 위협요인 ex) 보유자산 : 기술력, 브랜드 인지도, 유통망 등 ex) 문제점 : 마케팅 예산 부족, 인력 부족, 전문성 부족 | C5: 3000001 | D5: 3000002 | E5: 3000003 | F5: 내부강점 : 다양한 계층의 컨텐츠, 리뷰 충성도, 이용자 커뮤니케이션, 국외 OTT 협업 약점 : 낮은 점유율, 높은 인지도의 컨텐츠 부족, 자체 컨텐츠 부족, 보유 컨텐츠 대비 잠재 유저 인지 낮음 자산(기회 요소) : 충성도 높은 고객층, 왓챠 미진출 경쟁사 OTT 컨텐츠 섹터 위협요인 : 적은 이용자 수, 신규 유입자, 경쟁 OTT의 컨텐츠 다각화
A6: Customer(고객 분석) | B6: 성별, 나이, 직업, 거주지, 생활 패턴, 고객 니즈, 제품 및 서비스 사용 패턴 | C6: 4000001 | D6: 4000002 | E6: 4000003 | F6: 성별: 전 성별 / 나이 : 10-60대(영화-영상 매체 익숙), 롱폼 콘텐츠 컨슈머 고객 니즈 : 홈 컨텐츠 소비, 타 OTT에 없는 컨텐츠 소비 제품 및 서비스 사용 패턴 : 개인 사용, (집중 시청자 / 비집중 시청자)
A7: Competitor(경쟁사 분석) | B7: 대표 경쟁사 : 1~2곳, 경쟁사 강, 약점, 차별화 포인트 비교요소 : 제품, UX, 가격정보, 광고문구, 디자인 등 | C7: 3000001 | D7: 3000002 | E7: 3000003 | F7: 대표 경쟁사 : Netplix, 웨이브-티빙 경쟁사 강점 : Netplix~자체 제작 컨텐츠, 컨텐츠 파워 -> 자체제작 및 인기 컨텐츠 사용 충성 약점 : 비인기 컨텐츠를 수용X, 인기 컨텐츠 집중 전략 / 신규 유저 확보 어려움 Wave : 국내 드라마-영화 및 스포츠 컨텐츠 전속 계약 -> 많은 유저, 지속적 사용 약점: 국내 컨텐츠에 큰 의존, 새로운 컨텐츠 부족 비교: Netplixe 자사 대비컨텐츠 파워 높음, But 컨텐츠 다양성 부족 / 세분화된 카테고리 부족, 리뷰 시스템 미흡 Wave: 자사 대비 컨텐츠 파워 낮음, 매력적요소 낮음, 기존 컨텐츠를 다시 사용, 홍보 및 마케팅 부족
A8: 구성 요소 | B8: 의미 | F8: 예시
A9: S(Strengths) | B9: 내부강점 : 잘하고 있는 것, 경쟁력 | F9: 브랜드 인지도, 기술력, 충성 고객
A10: W(Weakness) | B10: 내부약점 : 바죽한 점, 개선 필요 요소 | F10: 예산 부족, UX 미흡, 충성 고객
A11: O(Opportunity) | B11: 외부기회 : 긍정적 외부 환경 변화 | F11: 소비 트렌드 변화
A12: T(Threats) | B12: 외부 위협 요소 : 부정적 요소 | F12: 통제 불능 위험

Sheet SWOT 전략 수립
A2: *SWOT 전략수립
A3: 브랜드명 : 왓챠
A4: Strenght(강점) -> 3C (Company) | C4: 광고비 | D4: 광고비 | E4: 광고비 | F4: Weakness(약점) ->3C(Company)
A5: 다양한 계층의 컨텐츠, 리뷰 충성도, 이용자 커뮤니케이션, 국외 OTT 플랫폼과 협업, 웹툰 - 소설 타 컨텐츠로 진출 리뷰 데이터 확보중 | F5: 낮은 점유율, 높은 인지도의 컨텐츠 부족, 자체 컨텐츠 부족, 보유 컨텐츠 대비 잠재 유저 인지 낮음 -> 주변부 OTT라는 인식 + 낮은 자금 조달력 기획 + 개발 능력 확보 부족
A7: Opportunities(기회) -> (Cumstomer) | C7: 광고비 | D7: 광고비 | E7: 광고비 | F7: Threats(위험) -> (Competitor)
A8: 충성도 높은 고객층, 왓챠 미진출 경쟁사 OTT 컨텐츠 섹터, 대형 OTT에서 미진한 컨텐츠 섹터 산업 구조의 변화~블록버스터 컨텐츠 수익률 하락 타 플랫폼의 텍스트 리뷰 데이터X | F8: 적은 이용자 수, 신규 유입자, 경쟁 OTT의 컨텐츠 다각화, 시장 경쟁 심화, 기초 IP 부족, MOUS 컨텐츠 없음
A10: SO 전략 | C10: 광고비 | D10: 광고비 | E10: 광고비 | F10: WT 전략
A11: 외국 컨텐츠 IP 라이센스 국내 유통 계약 -> 자체 제작 컨텐츠 제작 + 웹툰 및 소설등 낮은 단가의 대량의 IP를 가질 수 있음 외국 플랫품과의 협업으로 외국 OTT 시장 진출 + 리뷰 데이터를 이용한 팬덤 컨텐츠 자체 제작 | F11: 주변부 시장 접근 + 충성도 높은 고객 확보 -> B급 컨텐츠 확보 및 스낵 컬처 OTT 성장 가능성 기존 대형 OTT가 진입하지 못한 시장 확보 + IP 확보 "문화 산업 중 대안적 컨텐츠 플랫폼 시장 + 문화 컨텐츠 다변화 전략, 닛치 시장 집중 공략"
C20: ex) 20댕 여성, MZ 직장인
C21: 수도권 고객, 제주 여행객
C22: 자주 구매하는 고객, 앱을 1주 3회 이상 사용 고객
C23: 환경을 중시하는 고객, 트렌디한 소비를 즐기는 고객

Sheet STP 전략 수립
B1: *3C - > SWOT -> STP 전략 수립 프로세스
B2: 단계 | C2: 내용 | F2: 예시 | J2: 4P => product (플랫폼 가능)
B3: 1단계 | C3: 가상의 브랜드 선정(*실존 // 가상) | F3: 무신사, 다이소, 토스 etc | J3: 플랫폼 만의 장점을 부각시켜야 함! => 차별화 전략으로
B4: 2단계 | C4: 3C 분석 (Company. Customer, Competitor) | F4: Company : 자사 강점, 내부 리소스, 마케팅 전분 인력, UI UX | J4: 콘텐츠 보다는 플랫폼의 성격에 집중해야함!!
F5: Customer : 2030 여성 직장인, 주말 리프레쉬를 선호함
F6: Competitor : 멤버십 제도 구체화, 생산인프라 구축 -> 원가 절감, 브랜드 인지도, 충성고객 확보
B7: 3단계 | C7: SWOT 분석 (내부/외부 요인 도출 -> 전략 수립) | F7: Strength : 당일 배송 가능, 충성도 높은 고객 확보
F8: Weakness : 원가 부담으로 인한 가격 경쟁력 약함, 브랜도 인지도 낮음
F9: Opportunity : 1인가구 증가 추세, 자녀 출산률 감소 -> 자녀 교육비 투자 비용 상승
F10: Threat : 글로벌 대형 브랜드 시장진출, 동종 업계 유사 서비스의 과포화상태
B11: 4단계 | C11: STP 전략 구성 (*세분화 -> 타겟팅 -> 포지셔닝) | F11: Segmentation : 수도권 거주 / 직장인 / 친환경 1인 가구 직장인
F12: Targeting : 주 3회 이상 배달 음식을 시켜먹는 20-30대 직장인
F13: Positioning : 프로 혼밥러를 위한 건강하고 빠른 반찬 정기배송 런칭

Sheet STP 전략 수립_Mission
B1: *3C - > SWOT -> STP 전략 수립 프로세스
B2: 단계 | C2: 내용
B3: 1단계 | C3: 가상의 브랜드 선정(*실존 // 가상) | F3: 왓챠
B4: 2단계 | C4: 3C 분석 (Company. Customer, Competitor) | F4: Company : 다양한 계층의 컨텐츠, 리뷰 충성도, 이용자 커뮤니케이션, 국외 OTT 협업 왓챠 미진출 경쟁사 OTT 컨텐츠 섹터 /적은 이용자 수, 신규 유입자, 경쟁 OTT의 컨텐츠 다각화
F5: Customer : 타 OTT 플랫폼에서 자신과 핍진한 컨텐츠를 찾지 못한 유저, OTT 플랫폼을 잠재, 현재적 사용자 모두
F6: Copetiton : 낮은 점유율, 높은 인지도의 컨텐츠 부족, 자체 컨텐츠 부족, 보유 컨텐츠 대비 브랜드 인식, 컨텐츠 인식 부족
B7: 3단계 | C7: SWOT 분석 (내부/외부 요인 도출 -> 전략 수립) | F7: Strength : 다양한 계층의 컨텐츠, 리뷰 충성도, 이용자 커뮤니케이션, 국외 OTT 플랫폼과 협업, 웹툰 - 소설 타 컨텐츠로 진출, 리뷰 데이터 확보중
F8: Weakness : 낮은 점유율, 높은 인지도의 컨텐츠 부족, 자체 컨텐츠 부족, 보유 컨텐츠 대비 잠재 유저 인지 낮음 -> 주변부 OTT라는 인식 + 낮은 자금 조달력,기획 + 개발 능력 확보 부족
F9: Opportunity : 충성도 높은 고객층, 왓챠 미진출 경쟁사 OTT 컨텐츠 섹터, 대형 OTT에서 미진한 컨텐츠 섹터, 산업 구조의 변화 ~블록버스터 컨텐츠 수익률 하락, 타 플랫폼의 텍스트 리뷰 데이터X
F10: Threat : 적은 이용자 수, 신규 유입자, 경쟁 OTT의 컨텐츠 다각화, 시장 경쟁 심화, 기초 IP 부족, MOUS 컨텐츠 없음
B11: 4단계 | C11: STP 전략 구성 (*세분화 -> 타겟팅 -> 포지셔닝) | F11: Segmentation : 전국 거주 / 텍스트 리뷰를 중시하는 이용자 / 대형 OTT 컨텐츠의 부족을 느끼는 유저
F12: Targeting : 웹툰 / 웹소설 / 영화 컨텐츠를 한번의 구독으로 이용하려는 유저, 대형 OTT에서 런칭하지 않은 닛치 시장에 속한 컨텐츠를 소비 희망하는 유저 + 개인 추천 알고리즘 세분화!
F13: Positioning : 동일 or 더 높은 가격, 자신이 찾는 컨텐츠와 그것과 연계된 컨텐츠를 위해 더 높은 금액을 소비 할 수 있는 유저 / 다양한 장르, 주변부 장르 취향

Sheet RFM 분석
B2: *RFM 모델 활용 디지털 마케팅 전략 수립
B3: *User Research -> 1차 STP -> 서비스 런칭 -> RFM Model -> 2차 STP
B4: 1) User Research
B5: 20-30대 여성을 대상 설문조사 : "성분이 안전한 기초 화장품" 선호 피드백 확인
B6: 초기 페르소나 도출 : "민감성 피부", "사용자 리뷰 꼼꼼히 읽는 편", "직장인"
B7: 2. RFM Model 분석
B8: 최근 30일 이내 2회 이상 구매한 고객 대부분이 30대 초반 -> 평균 구매 금액 3만원 이상
B9: 실제 리뷰 작성 시, "재구매","믿고 쓰는"이라는 단어를 많이 사용하는 고객 -> 타 사용자의 리뷰에서도 다음과 같은 키워드에 많은 영향을 받더라
B10: 3. STP 전략 수립 가능
B11: S (Segmentation) : 민감성 피부 / 30대초반 경제력 확보 평균구매 금액 3만원 이상 / 중저가 가격 선호
B12: T (Targeting) : 30대 초반 직장 여성 중 민감성 피부 고객
B13: P (Positioning) : "피부과도 인정한 믿을 수 있는 성분으로 오픈마켓 기초부분 재구매율 1위를 달성한 믿고쓰는 독도토닉"

Sheet RAW_DATA
B2: *RFM 데이터 생성
B3: 1) Raw Data : 실제 구매고객들의 데이터가 필요!
B4: No | C4: User Name | D4: User Id | E4: Purchase Date | F4: Amount
B5: 1 | C5: 현빈 | D5: A001 | E5: 45805 | F5: 8000
B6: 2 | C6: 현빈 | D6: A001 | E6: 45809 | F6: 12000
B7: 3 | C7: 현빈 | D7: A001 | E7: 45836 | F7: 32000
B8: 4 | C8: 전지현 | D8: A002 | E8: 45678 | F8: 7000
B9: 5 | C9: 원빈 | D9: A003 | E9: 45717 | F9: 25000
B10: 6 | C10: 원빈 | D10: A003 | E10: 45838 | F10: 30000
B11: 7 | C11: 김혜수 | D11: A004 | E11: 45792 | F11: 15000
B12: 8 | C12: 비스트 | D12: A006 | E12: 45821 | F12: 8000

Sheet RFM Model
A2: *RFM 데이터 생성
A3: 2) RFM Model : 실제 구매고객들의 데이터를 활용한 주요고객 및 페르소나 도출목적
A4: No | B4: User Name | C4: User Id | D4: Purchase Date | E4: Amount | G4: User ID | H4: Last Purchase | I4: Recency | J4: Frequence | K4: Monetary | L4: R.score | M4: F.score | N4: M.score | O4: RFM code | P4: Segment
A5: 1 | B5: 현빈 | C5: A001 | D5: 2025.05.28 | E5: 8000 | G5: A001 | H5: =_xlfn.MAXIFS(RAW_DATA!$E$5:$E$12,RAW_DATA!$D$5:$D$12,G5) -> 45836 | I5: =TODAY()-H5 -> 30 | J5: =COUNTIFS(RAW_DATA!D5:$D$12,G5) -> 3 | K5: =SUMIFS(RAW_DATA!F5:$F$12,RAW_DATA!D5:$D$12,G5) -> 52000 | L5: =IF(I5<=20,5,IF(I5<=40,4,IF(I5<=60,3,IF(I5<=90,2,1)))) -> 4 | M5: =IF(J5>=3,5,IF(J5>=2,4,3)) -> 5 | N5: =IF(K5>=50000,5,IF(K5>=20000,4,IF(K5>=10000,3,2))) -> 5 | O5: =TEXT(L5,"0")&TEXT(M5,"0")&TEXT(N5,"0") -> 455 | P5: =IF(O5="555","Best",IF(L5<=2,"At Risk","General")) -> General
A6: 2 | B6: 전지현 | C6: A002 | D6: 2025.01.21 | E6: 7000 | G6: A002 | H6: =_xlfn.MAXIFS(RAW_DATA!$E$5:$E$12,RAW_DATA!$D$5:$D$12,G6) -> 45678 | I6: =TODAY()-H6 -> 188 | J6: =COUNTIFS(RAW_DATA!D6:$D$12,G6) -> 1 | K6: =SUMIFS(RAW_DATA!F6:$F$12,RAW_DATA!D6:$D$12,G6) -> 7000 | L6: =IF(I6<=20,5,IF(I6<=40,4,IF(I6<=60,3,IF(I6<=90,2,1)))) -> 1 | M6: =IF(J6>=3,5,IF(J6>=2,4,3)) -> 3 | N6: =IF(K6>=50000,5,IF(K6>=20000,4,IF(K6>=10000,3,2))) -> 2 | O6: =TEXT(L6,"0")&TEXT(M6,"0")&TEXT(N6,"0") -> 132 | P6: =IF(O6="555","Best",IF(L6<=2,"At Risk","General")) -> At Risk
A7: 3 | B7: 원빈 | C7: A003 | D7: 2025.03.01 | E7: 25000 | G7: A003 | H7: =_xlfn.MAXIFS(RAW_DATA!$E$5:$E$12,RAW_DATA!$D$5:$D$12,G7) -> 45838 | I7: =TODAY()-H7 -> 28 | J7: =COUNTIFS(RAW_DATA!D7:$D$12,G7) -> 2 | K7: =SUMIFS(RAW_DATA!F7:$F$12,RAW_DATA!D7:$D$12,G7) -> 55000 | L7: =IF(I7<=20,5,IF(I7<=40,4,IF(I7<=60,3,IF(I7<=90,2,1)))) -> 4 | M7: =IF(J7>=3,5,IF(J7>=2,4,3)) -> 4 | N7: =IF(K7>=50000,5,IF(K7>=20000,4,IF(K7>=10000,3,2))) -> 5 | O7: =TEXT(L7,"0")&TEXT(M7,"0")&TEXT(N7,"0") -> 445 | P7: =IF(O7="555","Best",IF(L7<=2,"At Risk","General")) -> General
A8: 4 | B8: 김혜수 | C8: A004 | D8: 2025.05.15 | E8: 15000 | G8: A004 | H8: =_xlfn.MAXIFS(RAW_DATA!$E$5:$E$12,RAW_DATA!$D$5:$D$12,G8) -> 45792 | I8: =TODAY()-H8 -> 74 | J8: =COUNTIFS(RAW_DATA!D8:$D$12,G8) -> 1 | K8: =SUMIFS(RAW_DATA!F8:$F$12,RAW_DATA!D8:$D$12,G8) -> 15000 | L8: =IF(I8<=20,5,IF(I8<=40,4,IF(I8<=60,3,IF(I8<=90,2,1)))) -> 2 | M8: =IF(J8>=3,5,IF(J8>=2,4,3)) -> 3 | N8: =IF(K8>=50000,5,IF(K8>=20000,4,IF(K8>=10000,3,2))) -> 3 | O8: =TEXT(L8,"0")&TEXT(M8,"0")&TEXT(N8,"0") -> 233 | P8: =IF(O8="555","Best",IF(L8<=2,"At Risk","General")) -> At Risk
A9: 5 | B9: 비스트 | C9: A005 | D9: 2025.06.13 | E9: 8000 | G9: A006 | H9: =_xlfn.MAXIFS(RAW_DATA!$E$5:$E$12,RAW_DATA!$D$5:$D$12,G9) -> 45821 | I9: =TODAY()-H9 -> 45 | J9: =COUNTIFS(RAW_DATA!D9:$D$12,G9) -> 1 | K9: =SUMIFS(RAW_DATA!F9:$F$12,RAW_DATA!D9:$D$12,G9) -> 8000 | L9: =IF(I9<=20,5,IF(I9<=40,4,IF(I9<=60,3,IF(I9<=90,2,1)))) -> 3 | M9: =IF(J9>=3,5,IF(J9>=2,4,3)) -> 3 | N9: =IF(K9>=50000,5,IF(K9>=20000,4,IF(K9>=10000,3,2))) -> 2 | O9: =TEXT(L9,"0")&TEXT(M9,"0")&TEXT(N9,"0") -> 332 | P9: =IF(O9="555","Best",IF(L9<=2,"At Risk","General")) -> General

Sheet RFM Model (2)
A1: *RFM 활용 페르소나 제작 실습
A2: RFM 데이터 기반, 최우선 공략 Target 고객 페르소나 도출
B3: Segment | C3: 고객수 | D3: 비고 | F3: 항목 | G3: 내용
B4: Best | C4: 1 | D4: A001 | F4: 이름 | G4: 민혜린 (가명)
B5: At Risk | C5: 1 | D5: A002 | F5: 나이 / 성별 | G5: 33세 / 여성
B6: General | C6: 3 | D6: A003, A004, A005 | F6: 직업 | G6: 금융권 사무직
F7: 라이프스타일 | G7: 평일 퇴근 후 스마트폰 쇼핑, 합리적이지만 프리미엄 상품에도 관심
B8: 항목 | C8: 내용 | F8: 구매 행동 | G8: 프리미엄 포장, 정기배송 옵션, 맞춤형 혜택
B9: 타겟 세그먼트 | C9: Best | F9: 디지털 행동 | G9: 앱푸시 잘 반응, SNS에서 신제품 출시 검색
B10: 포함 고객 | C10: A001 | F10: 니즈 / 문제 | G10: "품질 확신"이 있는 브랜드만 반복 구매/쿠폰 & 리뷰가 구매 결정에 중요
B11: 행동 특성 | C11: Recency = 16일 / Frequence = 3회 / Monetary = 52000
B12: 기회 요소 | C12: 정기 구독 유도, 고액 구매시 보상 ->만족도
B13: 위험요소 | C13: 해당 고객이 차지하는 LTV 비중이 높아, 탈퇴시 매출 및 영업이익 손실에 영향이 큼 -> 별도의 고객 관리 필요
B14: 마케팅 전략 | C14: 1:1 혜택 메세지 / VIP 고객 전용 쿠폰 / 신제품 출시 ->사전 공개 혜택
